Workbook
Name Administration: Subcategories!$D$2:$D$9
Name Capital_Financing: Subcategories!$E$2:$E$7
Name Marketing: Subcategories!$B$2:$B$8
Name Revenue: Subcategories!$A$2:$A$8
Name Technology: Subcategories!$C$2:$C$8

Sheet Subcategories
A1: Revenue | B1: Marketing | C1: Technology | D1: Administration | E1: Capital & Financing
A2: Platform Fees | B2: Paid Advertising | C2: Marketplace Platform | D2: Accounting & Fiduciary | E2: Share Capital
A3: Other Operating Revenue | B3: Events & Offline Marketing | C3: Hosting & Infrastructure | D3: Legal & Compliance | E3: Founder Contributions
A4: Affiliate Commissions | B4: Travel (marketing-related) | C4: SaaS Tools | D4: Banking Fees | E4: Investor Contributions
A5: Insurance Commissions | B5: Content & SEO | C5: Domains & Email | D5: Admin Subscriptions | E5: Loans
A6: Refunds & Reimbursements | B6: PR | C6: Payments & Transaction Fees | D6: Insurance | E6: Grants & Subsidies
A7: Interest Income | B7: Design & Creative | C7: Hardware | D7: Taxes & VAT | E7: Other
A8: Other | B8: Other | C8: Other | D8: Office & Supplies
D9: Other

Sheet Lists
A1: Categories (from config)
A2: Revenue | B2: Platform Fees, Other Operating Revenue, Affiliate Commissions, Insurance Commissions, Refunds & Reimbursements, Interest Income, Other
A3: Marketing | B3: Paid Advertising, Events & Offline Marketing, Travel (marketing-related), Content & SEO, PR, Design & Creative, Other
A4: Technology | B4: Marketplace Platform, Hosting & Infrastructure, SaaS Tools, Domains & Email, Payments & Transaction Fees, Hardware, Other
A5: Administration | B5: Accounting & Fiduciary, Legal & Compliance, Banking Fees, Admin Subscriptions, Insurance, Taxes & VAT, Office & Supplies, Other
A6: Capital & Financing | B6: Share Capital, Founder Contributions, Investor Contributions, Loans, Grants & Subsidies, Other

Sheet Transactions
A1: account_iban | B1: booking_date | C1: extract_nr | D1: transaction_nr | E1: counterparty_account | F1: counterparty | G1: street | H1: city | I1: description | J1: value_date | K1: amount | L1: currency | M1: bic | N1: country_code | O1: communications | P1: raw_type | Q1: direction | R1: month | S1: quarter | T1: category | U1: subcategory | V1: category | W1: subcategory
A2: BE39 0689 5704 9719 | B2: 2026-03-02 | E2: FR76 3000 3034 5000 0205 6663 740 | F2: Yogi Editions | I2: VIREMENT BELFIUS MOBILE VERS FR76 3000 3034 5000 0205 6663 740 Yogi Editions FC-26543 REF. : 0905471032838 VAL. 02-03 | J2: 2026-03-02 | K2: -750 | L2: EUR | M2: SOGEFRPP | O2: FC-26543 | P2: VIREMENT BELFIUS MOBILE VERS FR | Q2: out | R2: 2026-03 | S2: 2026-Q1 | T2: Marketing | U2: Events & Offline Marketing
A3: BE39 0689 5704 9719 | B3: 2026-03-02 | F3: MICROSOFT*ADS-G120U356 | H3: 18 MSBILL.INFO | I3: PAIEMENT DEBITMASTERCARD VIA eCommerce 01/03 MICROSOFT*ADS-G120U356 MSBILL. INFO IE 50,00 EUR CARTE N° 5255 0604 0603 9797 - de Biolley Sebastian REF. : 0801T32086197 VAL. 02-03 | J3: 2026-03-02 | K3: -50 | L3: EUR | N3: IE | O3: PAIEMENT DEBITMASTERCARD VIA eCommerce 01/03 MICROSOFT*ADS-G120U356 MSBILL. INFO IE 50,00 EUR CARTE N° 5255 0604 0603 9797 - de Biolley Sebastian REF. : 0801T32086197 VAL. 02-03 | P3: PAIEMENT DEBITMASTERCARD VIA | Q3: out | R3: 2026-03 | S3: 2026-Q1 | T3: Marketing | U3: Paid Advertising
A4: BE39 0689 5704 9719 | B4: 2026-03-02 | F4: MICROSOFT*ADS-G120U356 | H4: 18 MSBILL.INFO | I4: PAIEMENT DEBITMASTERCARD VIA eCommerce 28/02 MICROSOFT*ADS-G120U356 MSBILL. INFO IE 50,00 EUR CARTE N° 5255 0604 0603 9797 - de Biolley Sebastian REF. : 0801S32778200 VAL. 02-03 | J4: 2026-03-02 | K4: -50 | L4: EUR | N4: IE | O4: PAIEMENT DEBITMASTERCARD VIA eCommerce 28/02 MICROSOFT*ADS-G120U356 MSBILL. INFO IE 50,00 EUR CARTE N° 5255 0604 0603 9797 - de Biolley Sebastian REF. : 0801S32778200 VAL. 02-03 | P4: PAIEMENT DEBITMASTERCARD VIA | Q4: out | R4: 2026-03 | S4: 2026-Q1 | T4: Marketing | U4: Paid Advertising
A5: BE39 0689 5704 9719 | B5: 2026-03-02 | F5: Google ADS3215138576 | H5: D04 E5W5 DUBLIN 4 | I5: PAIEMENT DEBITMASTERCARD 01/03 Google ADS3215138576 DUBLIN 4 IE 304,19 EUR CARTE N° 5255 0604 0603 9797 - de Biolley Sebastian REF. : 0801S32C92398 VAL. 02-03 | J5: 2026-03-02 | K5: -304.19 | L5: EUR | N5: IE | O5: PAIEMENT DEBITMASTERCARD 01/03 Google ADS3215138576 DUBLIN 4 IE 304,19 EUR CARTE N° 5255 0604 0603 9797 - de Biolley Sebastian REF. : 0801S32C92398 VAL. 02-03 | P5: PAIEMENT DEBITMASTERCARD | Q5: out | R5: 2026-03 | S5: 2026-Q1 | T5: Marketing | U5: Paid Advertising
A6: BE39 0689 5704 9719 | B6: 2026-03-02 | F6: MICROSOFT IRELAND OPER | H6: D02 R296 DUBLIN | I6: PAIEMENT DEBITMASTERCARD 28/02 MICROSOFT IRELAND OPER DUBLIN IE 50,00 EUR CARTE N° 5255 0604 0603 9797 - de Biolley Sebastian REF. : 0801S32838966 VAL. 02-03 | J6: 2026-03-02 | K6: -50 | L6: EUR | N6: IE | O6: PAIEMENT DEBITMASTERCARD 28/02 MICROSOFT IRELAND OPER DUBLIN IE 50,00 EUR CARTE N° 5255 0604 0603 9797 - de Biolley Sebastian REF. : 0801S32838966 VAL. 02-03 | P6: PAIEMENT DEBITMASTERCARD | Q6: out | R6: 2026-03 | S6: 2026-Q1 | T6: Marketing | U6: Paid Advertising
A7: BE39 0689 5704 9719 | B7: 2026-02-26 | F7: MICROSOFT*ADS-G120U356 | H7: 18 MSBILL.INFO | I7: PAIEMENT DEBITMASTERCARD 25/02 MICROSOFT*ADS-G120U356 MSBILL.INFO IE 50,00 EUR CARTE N° 5255 0604 0603 9797 - de Biolley Sebastian REF. : 0801S2Q144487 VAL. 26-02 | J7: 2026-02-26 | K7: -50 | L7: EUR | N7: IE | O7: PAIEMENT DEBITMASTERCARD 25/02 MICROSOFT*ADS-G120U356 MSBILL.INFO IE 50,00 EUR CARTE N° 5255 0604 0603 9797 - de Biolley Sebastian REF. : 0801S2Q144487 VAL. 26-02 | P7: PAIEMENT DEBITMASTERCARD | Q7: out | R7: 2026-02 | S7: 2026-Q1 | T7: Marketing | U7: Paid Advertising
A8: BE39 0689 5704 9719 | B8: 2026-02-23 | C8: 5 | D8: 21 | F8: BIZAY | H8: 2560 628 BE | I8: PAIEMENT DEBITMASTERCARD 21/02 BIZAY BE PT 16,63 EUR CARTE N° 5255 0604 0603 9797 - de Biolley Sebastian REF. : 0801S2N624862 VAL. 23-02 | J8: 2026-02-23 | K8: -16.63 | L8: EUR | N8: PT | O8: PAIEMENT DEBITMASTERCARD 21/02 BIZAY BE PT 16,63 EUR CARTE N° 5255 0604 0603 9797 - de Biolley Sebastian REF. : 0801S2N624862 VAL. 23-02 | P8: PAIEMENT DEBITMASTERCARD | Q8: out | R8: 2026-02 | S8: 2026-Q1 | T8: Administration | U8: Office & Supplies
A9: BE39 0689 5704 9719 | B9: 2026-02-23 | C9: 5 | D9: 20 | F9: Magnis Group bvba | H9: 3500 +3289694906 | I9: PAIEMENT DEBITMASTERCARD 20/02 Magnis Group bvba +3289694906 BE 346,00 EUR CARTE N° 5255 0604 0603 9797 - de Biolley Sebastian REF. : 0801S2N236353 VAL. 23-02 | J9: 2026-02-23 | K9: -346 | L9: EUR | N9: BE | O9: PAIEMENT DEBITMASTERCARD 20/02 Magnis Group bvba +3289694906 BE 346,00 EUR CARTE N° 5255 0604 0603 9797 - de Biolley Sebastian REF. : 0801S2N236353 VAL. 23-02 | P9: PAIEMENT DEBITMASTERCARD | Q9: out | R9: 2026-02 | S9: 2026-Q1 | T9: Marketing | U9: Events & Offline Marketing
A10: BE39 0689 5704 9719 | B10: 2026-02-23 | C10: 5 | D10: 19 | F10: BIZAY | H10: 2560 628 BE | I10: PAIEMENT DEBITMASTERCARD 21/02 BIZAY BE PT 79,61 EUR CARTE N° 5255 0604 0603 9797 - de Biolley Sebastian REF. : 0801S2N624967 VAL. 23-02 | J10: 2026-02-23 | K10: -79.61 | L10: EUR | N10: PT | O10: PAIEMENT DEBITMASTERCARD 21/02 BIZAY BE PT 79,61 EUR CARTE N° 5255 0604 0603 9797 - de Biolley Sebastian REF. : 0801S2N624967 VAL. 23-02 | P10: PAIEMENT DEBITMASTERCARD | Q10: out | R10: 2026-02 | S10: 2026-Q1 | T10: Administration | U10: Office & Supplies
A11: BE39 0689 5704 9719 | B11: 2026-02-19 | C11: 5 | D11: 18 | F11: MICROSOFT*ADVERTISING | H11: 18 MSBILL.INFO | I11: PAIEMENT DEBITMASTERCARD 18/02 MICROSOFT*ADVERTISING MSBILL.INFO IE 50,00 EUR CARTE N° 5255 0604 0603 9797 - de Biolley Sebastian REF. : 0801S2J136810 VAL. 19-02 | J11: 2026-02-19 | K11: -50 | L11: EUR | N11: IE | O11: PAIEMENT DEBITMASTERCARD 18/02 MICROSOFT*ADVERTISING MSBILL.INFO IE 50,00 EUR CARTE N° 5255 0604 0603 9797 - de Biolley Sebastian REF. : 0801S2J136810 VAL. 19-02 | P11: PAIEMENT DEBITMASTERCARD | Q11: out | R11: 2026-02 | S11: 2026-Q1 | T11: Marketing | U11: Paid Advertising
A12: BE39 0689 5704 9719 | B12: 2026-02-18 | C12: 5 | D12: 17 | E12: IT03 Q030 6905 1421 0000 0017 641 | F12: MECHILLI ROCCO | I12: VIREMENT BELFIUS MOBILE VERS IT03 Q030 6905 1421 0000 0017 641 MECHILLI ROCCO Social media strategy REF. : 090541832I399 VAL. 18-02 | J12: 2026-02-18 | K12: -600 | L12: EUR | M12: BCITITMM | O12: Social media strategy | P12: VIREMENT BELFIUS MOBILE VERS IT | Q12: out | R12: 2026-02 | S12: 2026-Q1 | T12: Marketing | U12: Events & Offline Marketing
A13: BE39 0689 5704 9719 | B13: 2026-02-16 | C13: 4 | D13: 16 | F13: Leboncoin | H13: 75010 Paris | I13: PAIEMENT DEBITMASTERCARD VIA eCommerce 14/02 Leboncoin Paris FR 29,03 EUR CARTE N° 5255 0604 0603 9797 - de Biolley Sebastian REF. : 0801S2G574742 VAL. 16-02 | J13: 2026-02-16 | K13: -29.03 | L13: EUR | N13: FR | O13: PAIEMENT DEBITMASTERCARD VIA eCommerce 14/02 Leboncoin Paris FR 29,03 EUR CARTE N° 5255 0604 0603 9797 - de Biolley Sebastian REF. : 0801S2G574742 VAL. 16-02 | P13: PAIEMENT DEBITMASTERCARD VIA | Q13: out | R13: 2026-02 | S13: 2026-Q1 | T13: Marketing | U13: Paid Advertising
A14: BE39 0689 5704 9719 | B14: 2026-02-16 | C14: 4 | D14: 15 | F14: Leboncoin | H14: 75010 Paris | I14: PAIEMENT DEBITMASTERCARD VIA eCommerce 14/02 Leboncoin Paris FR 29,03 EUR CARTE N° 5255 0604 0603 9797 - de Biolley Sebastian REF. : 0801S2G574647 VAL. 16-02 | J14: 2026-02-16 | K14: -29.03 | L14: EUR | N14: FR | O14: PAIEMENT DEBITMASTERCARD VIA eCommerce 14/02 Leboncoin Paris FR 29,03 EUR CARTE N° 5255 0604 0603 9797 - de Biolley Sebastian REF. : 0801S2G574647 VAL. 16-02 | P14: PAIEMENT DEBITMASTERCARD VIA | Q14: out | R14: 2026-02 | S14: 2026-Q1 | T14: Marketing | U14: Paid Advertising
A15: BE39 0689 5704 9719 | B15: 2026-02-16 | C15: 4 | D15: 14 | F15: Google ADS3215138576 | H15: D04 E5W5 DUBLIN 4 | I15: PAIEMENT DEBITMASTERCARD 15/02 Google ADS3215138576 DUBLIN 4 IE 200,00 EUR CARTE N° 5255 0604 0603 9797 - de Biolley Sebastian REF. : 0801S2GD66184 VAL. 16-02 | J15: 2026-02-16 | K15: -200 | L15: EUR | N15: IE | O15: PAIEMENT DEBITMASTERCARD 15/02 Google ADS3215138576 DUBLIN 4 IE 200,00 EUR CARTE N° 5255 0604 0603 9797 - de Biolley Sebastian REF. : 0801S2GD66184 VAL. 16-02 | P15: PAIEMENT DEBITMASTERCARD | Q15: out | R15: 2026-02 | S15: 2026-Q1 | T15: Marketing | U15: Paid Advertising
A16: BE39 0689 5704 9719 | B16: 2026-02-09 | C16: 3 | D16: 13 | F16: www.cleverbridge.net | H16: 50670 Cologne | I16: PAIEMENT DEBITMASTERCARD 07/02 www. cleverbridge. net Cologne DE 9,67 USD FRAIS DE TRAITEMENT 0,52 EUR + TVA 0,11 EUR CARTE N° 5255 0604 0603 9797 - de Biolley Sebastian COURS DE CHANGE 1,176399035 REF. : 0801S29837546 VAL. 09-02 | J16: 2026-02-09 | K16: -8.85 | L16: EUR | N16: DE | O16: PAIEMENT DEBITMASTERCARD 07/02 www. cleverbridge. net Cologne DE 9,67 USD FRAIS DE TRAITEMENT 0,52 EUR + TVA 0,11 EUR CARTE N° 5255 0604 0603 9797 - de Biolley Sebastian COURS DE CHANGE 1,176399035 REF. : 0801S29837546 VAL. 09-02 | P16: PAIEMENT DEBITMASTERCARD | Q16: out | R16: 2026-02 | S16: 2026-Q1 | T16: Technology | U16: SaaS Tools
A17: BE39 0689 5704 9719 | B17: 2026-02-04 | C17: 3 | D17: 12 | F17: RENDER.COM | H17: 94107 SAN FRANCISCO | I17: PAIEMENT DEBITMASTERCARD VIA eCommerce 03/02 RENDER. COM SAN FRANCISCO US 26,00 USD FRAIS DE TRAITEMENT 0,69 EUR + TVA 0,14 EUR CARTE N° 5255 0604 0603 9797 - de Biolley Sebastian COURS DE CHANGE 1,177536328 REF. : 0801U24010489 VAL. 04-02 | J17: 2026-02-04 | K17: -22.91 | L17: EUR | N17: US | O17: PAIEMENT DEBITMASTERCARD VIA eCommerce 03/02 RENDER. COM SAN FRANCISCO US 26,00 USD FRAIS DE TRAITEMENT 0,69 EUR + TVA 0,14 EUR CARTE N° 5255 0604 0603 9797 - de Biolley Sebastian COURS DE CHANGE 1,177536328 REF. : 0801U24010489 VAL. 04-02 | P17: PAIEMENT DEBITMASTERCARD VIA | Q17: out | R17: 2026-02 | S17: 2026-Q1 | T17: Technology | U17: Hosting & Infrastructure
A18: BE39 0689 5704 9719 | B18: 2026-02-04 | C18: 3 | D18: 11 | F18: Leboncoin | H18: 75010 Paris | I18: PAIEMENT DEBITMASTERCARD 03/02 Leboncoin Paris FR 29,03 EUR CARTE N° 5255 0604 0603 9797 - de Biolley Sebastian REF. : 0801S24123642 VAL. 04-02 | J18: 2026-02-04 | K18: -29.03 | L18: EUR | N18: FR | O18: PAIEMENT DEBITMASTERCARD 03/02 Leboncoin Paris FR 29,03 EUR CARTE N° 5255 0604 0603 9797 - de Biolley Sebastian REF. : 0801S24123642 VAL. 04-02 | P18: PAIEMENT DEBITMASTERCARD | Q18: out | R18: 2026-02 | S18: 2026-Q1 | T18: Marketing | U18: Paid Advertising
A19: BE39 0689 5704 9719 | B19: 2026-02-02 | C19: 3 | D19: 10 | F19: Google ADS3215138576 | H19: D04 E5W5 DUBLIN 4 | I19: PAIEMENT DEBITMASTERCARD 01/02 Google ADS3215138576 DUBLIN 4 IE 83,59 EUR CARTE N° 5255 0604 0603 9797 - de Biolley Sebastian REF. : 0801S22C74223 VAL. 02-02 | J19: 2026-02-02 | K19: -83.59 | L19: EUR | N19: IE | O19: PAIEMENT DEBITMASTERCARD 01/02 Google ADS3215138576 DUBLIN 4 IE 83,59 EUR CARTE N° 5255 0604 0603 9797 - de Biolley Sebastian REF. : 0801S22C74223 VAL. 02-02 | P19: PAIEMENT DEBITMASTERCARD | Q19: out | R19: 2026-02 | S19: 2026-Q1 | T19: Marketing | U19: Paid Advertising
A20: BE39 0689 5704 9719 | B20: 2026-02-02 | C20: 3 | D20: 9 | E20: BE46 7320 5736 4336 | F20: Fiduciaire Digitale | I20: VIREMENT BELFIUS MOBILE VERS BE46 7320 5736 4336 Fiduciaire Digitale +++260/1003/41115+++ REF. : 0905436322232 VAL. 02-02 | J20: 2026-02-02 | K20: -907.5 | L20: EUR | M20: CREGBEBB | O20: +++260/1003/41115+++ | P20: VIREMENT BELFIUS MOBILE VERS BE | Q20: out | R20: 2026-02 | S20: 2026-Q1 | T20: Administration | U20: Accounting & Fiduciary
A21: BE39 0689 5704 9719 | B21: 2026-01-27 | C21: 2 | D21: 8 | F21: Google ADS3215138576 | H21: D04 E5W5 DUBLIN 4 | I21: PAIEMENT DEBITMASTERCARD 26/01 Google ADS3215138576 DUBLIN 4 IE 100,00 EUR CARTE N° 5255 0604 0603 9797 - de Biolley Sebastian REF. : 0801S1R113579 VAL. 27-01 | J21: 2026-01-27 | K21: -100 | L21: EUR | N21: IE | O21: PAIEMENT DEBITMASTERCARD 26/01 Google ADS3215138576 DUBLIN 4 IE 100,00 EUR CARTE N° 5255 0604 0603 9797 - de Biolley Sebastian REF. : 0801S1R113579 VAL. 27-01 | P21: PAIEMENT DEBITMASTERCARD | Q21: out | R21: 2026-01 | S21: 2026-Q1 | T21: Marketing | U21: Paid Advertising
A22: BE39 0689 5704 9719 | B22: 2026-01-26 | C22: 2 | D22: 7 | F22: MICROSOFT*ADVERTISING | H22: 18 MSBILL.INFO | I22: PAIEMENT DEBITMASTERCARD 23/01 MICROSOFT*ADVERTISING MSBILL.INFO IE 50,00 EUR CARTE N° 5255 0604 0603 9797 - de Biolley Sebastian REF. : 0801S1Q242382 VAL. 26-01 | J22: 2026-01-26 | K22: -50 | L22: EUR | N22: IE | O22: PAIEMENT DEBITMASTERCARD 23/01 MICROSOFT*ADVERTISING MSBILL.INFO IE 50,00 EUR CARTE N° 5255 0604 0603 9797 - de Biolley Sebastian REF. : 0801S1Q242382 VAL. 26-01 | P22: PAIEMENT DEBITMASTERCARD | Q22: out | R22: 2026-01 | S22: 2026-Q1 | T22: Marketing | U22: Paid Advertising
A23: BE39 0689 5704 9719 | B23: 2026-01-26 | C23: 2 | D23: 6 | F23: Google ADS3215138576 | H23: D04 E5W5 DUBLIN 4 | I23: PAIEMENT DEBITMASTERCARD 23/01 Google ADS3215138576 DUBLIN 4 IE 50,00 EUR CARTE N° 5255 0604 0603 9797 - de Biolley Sebastian REF. : 0801S1Q154860 VAL. 26-01 | J23: 2026-01-26 | K23: -50 | L23: EUR | N23: IE | O23: PAIEMENT DEBITMASTERCARD 23/01 Google ADS3215138576 DUBLIN 4 IE 50,00 EUR CARTE N° 5255 0604 0603 9797 - de Biolley Sebastian REF. : 0801S1Q154860 VAL. 26-01 | P23: PAIEMENT DEBITMASTERCARD | Q23: out | R23: 2026-01 | S23: 2026-Q1 | T23: Marketing | U23: Paid Advertising
A24: BE39 0689 5704 9719 | B24: 2026-01-20 | C24: 2 | D24: 5 | F24: AMAZON EU SARL | H24: 75017 PARIS | I24: PAIEMENT DEBITMASTERCARD 17/01 AMAZON EU SARL PARIS FR 44,93 EUR CARTE N° 5255 0604 0603 9797 - de Biolley Sebastian REF. : 0801U1K272040 VAL. 20-01 | J24: 2026-01-20 | K24: -44.93 | L24: EUR | N24: FR | O24: PAIEMENT DEBITMASTERCARD 17/01 AMAZON EU SARL PARIS FR 44,93 EUR CARTE N° 5255 0604 0603 9797 - de Biolley Sebastian REF. : 0801U1K272040 VAL. 20-01 | P24: PAIEMENT DEBITMASTERCARD | Q24: out | R24: 2026-01 | S24: 2026-Q1 | T24: Administration | U24: Office & Supplies
A25: BE39 0689 5704 9719 | B25: 2026-01-07 | C25: 1 | D25: 4 | I25: FRAIS D'EXPEDITION DE VOS AVIS BANCAIRES REF. : 0817016013612 VAL. 01-01 | J25: 2026-01-01 | K25: -5.98 | L25: EUR | O25: FRAIS D'EXPEDITION DE VOS AVIS BANCAIRES REF. : 0817016013612 VAL. 01-01 | P25: FRAIS D | Q25: out | R25: 2026-01 | S25: 2026-Q1 | T25: Administration | U25: Banking Fees
A26: BE39 0689 5704 9719 | B26: 2026-01-06 | C26: 1 | D26: 3 | F26: PROJECTIONHUB.COM | H26: 47356 MIDDLETOWN | I26: PAIEMENT DEBITMASTERCARD 05/01 PROJECTIONHUB. COM MIDDLETOWN US 95,20 USD FRAIS DE TRAITEMENT 1,43 EUR + TVA 0,30 EUR CARTE N° 5255 0604 0603 9797 - de Biolley Sebastian COURS DE CHANGE 1,171259860 REF. : 0801T16231003 VAL. 06-01 | J26: 2026-01-06 | K26: -83.01 | L26: EUR | N26: US | O26: PAIEMENT DEBITMASTERCARD 05/01 PROJECTIONHUB. COM MIDDLETOWN US 95,20 USD FRAIS DE TRAITEMENT 1,43 EUR + TVA 0,30 EUR CARTE N° 5255 0604 0603 9797 - de Biolley Sebastian COURS DE CHANGE 1,171259860 REF. : 0801T16231003 VAL. 06-01 | P26: PAIEMENT DEBITMASTERCARD | Q26: out | R26: 2026-01 | S26: 2026-Q1 | T26: Technology | U26: SaaS Tools
A27: BE39 0689 5704 9719 | B27: 2026-01-05 | C27: 1 | D27: 2 | F27: RENDER.COM | H27: 94107 SAN FRANCISCO | I27: PAIEMENT DEBITMASTERCARD VIA eCommerce 03/01 RENDER. COM SAN FRANCISCO US 26,00 USD FRAIS DE TRAITEMENT 0,69 EUR + TVA 0,14 EUR CARTE N° 5255 0604 0603 9797 - de Biolley Sebastian COURS DE CHANGE 1,171171245 REF. : 0801S15B32601 VAL. 05-01 | J27: 2026-01-05 | K27: -23.03 | L27: EUR | N27: US | O27: PAIEMENT DEBITMASTERCARD VIA eCommerce 03/01 RENDER. COM SAN FRANCISCO US 26,00 USD FRAIS DE TRAITEMENT 0,69 EUR + TVA 0,14 EUR CARTE N° 5255 0604 0603 9797 - de Biolley Sebastian COURS DE CHANGE 1,171171245 REF. : 0801S15B32601 VAL. 05-01 | P27: PAIEMENT DEBITMASTERCARD VIA | Q27: out | R27: 2026-01 | S27: 2026-Q1 | T27: Technology | U27: Hosting & Infrastructure
A28: BE39 0689 5704 9719 | B28: 2026-01-02 | C28: 1 | D28: 1 | F28: Google ADS3215138576 | H28: D04 E5W5 DUBLIN 4 | I28: PAIEMENT DEBITMASTERCARD 01/01 Google ADS3215138576 DUBLIN 4 IE 38,59 EUR CARTE N° 5255 0604 0603 9797 - de Biolley Sebastian REF. : 0801S12649869 VAL. 02-01 | J28: 2026-01-02 | K28: -38.59 | L28: EUR | N28: IE | O28: PAIEMENT DEBITMASTERCARD 01/01 Google ADS3215138576 DUBLIN 4 IE 38,59 EUR CARTE N° 5255 0604 0603 9797 - de Biolley Sebastian REF. : 0801S12649869 VAL. 02-01 | P28: PAIEMENT DEBITMASTERCARD | Q28: out | R28: 2026-01 | S28: 2026-Q1 | T28: Marketing | U28: Paid Advertising
A29: BE39 0689 5704 9719 | B29: 2025-12-17 | C29: 7 | D29: 29 | F29: SHARETRIBE | H29: 00130 HELSINKI | I29: PAIEMENT DEBITMASTERCARD VIA eCommerce 17/12 SHARETRIBE HELSINKI FI 3487,98 USD FRAIS DE TRAITEMENT 37,72 EUR + TVA 7,92 EUR CARTE N° 5255 0604 0603 9797 - de Biolley Sebastian COURS DE CHANGE 1,173700655 REF. : 0801UCH204038 VAL. 17-12 | J29: 2025-12-17 | K29: -3017.42 | L29: EUR | N29: FI | O29: PAIEMENT DEBITMASTERCARD VIA eCommerce 17/12 SHARETRIBE HELSINKI FI 3487,98 USD FRAIS DE TRAITEMENT 37,72 EUR + TVA 7,92 EUR CARTE N° 5255 0604 0603 9797 - de Biolley Sebastian COURS DE CHANGE 1,173700655 REF. : 0801UCH204038 VAL. 17-12 | P29: PAIEMENT DEBITMASTERCARD VIA | Q29: out | R29: 2025-12 | S29: 2025-Q4 | T29: Technology | U29: Marketplace Platform
A30: BE39 0689 5704 9719 | B30: 2025-12-10 | C30: 6 | D30: 28 | F30: GOOGLE*ADS3215138576 | H30: D04 E5W5 CC GOOGLE.COM | I30: PAIEMENT DEBITMASTERCARD 31/10 GOOGLE*ADS3215138576 CC GOOGLE.COM IE 49,64 EUR CARTE N° 5255 0604 0603 9797 - de Biolley Sebastian REF. : 0801SCA075188 VAL. 10-12 | J30: 2025-12-10 | K30: -49.64 | L30: EUR | N30: IE | O30: PAIEMENT DEBITMASTERCARD 31/10 GOOGLE*ADS3215138576 CC GOOGLE.COM IE 49,64 EUR CARTE N° 5255 0604 0603 9797 - de Biolley Sebastian REF. : 0801SCA075188 VAL. 10-12 | P30: PAIEMENT DEBITMASTERCARD | Q30: out | R30: 2025-12 | S30: 2025-Q4 | T30: Marketing | U30: Paid Advertising
A31: BE39 0689 5704 9719 | B31: 2025-12-08 | C31: 6 | D31: 27 | F31: Google ADS3215138576 | H31: D04 E5W5 DUBLIN 4 | I31: PAIEMENT DEBITMASTERCARD 06/12 Google ADS3215138576 DUBLIN 4 IE 10,00 EUR CARTE N° 5255 0604 0603 9797 - de Biolley Sebastian REF. : 0801SC8A03977 VAL. 08-12 | J31: 2025-12-08 | K31: -10 | L31: EUR | N31: IE | O31: PAIEMENT DEBITMASTERCARD 06/12 Google ADS3215138576 DUBLIN 4 IE 10,00 EUR CARTE N° 5255 0604 0603 9797 - de Biolley Sebastian REF. : 0801SC8A03977 VAL. 08-12 | P31: PAIEMENT DEBITMASTERCARD | Q31: out | R31: 2025-12 | S31: 2025-Q4 | T31: Marketing | U31: Paid Advertising
A32: BE39 0689 5704 9719 | B32: 2025-12-08 | C32: 6 | D32: 26 | E32: BE66 3631 4013 6243 | F32: It's so Good | I32: VIREMENT BELFIUS MOBILE VERS BE66 3631 4013 6243 It's so Good 69356dc65b01c REF. : 09054212C7157 VAL. 08-12 | J32: 2025-12-08 | K32: -121 | L32: EUR | M32: BBRUBEBB | O32: 69356dc65b01c | P32: VIREMENT BELFIUS MOBILE VERS BE | Q32: out | R32: 2025-12 | S32: 2025-Q4 | T32: Marketing | U32: Events & Offline Marketing
A33: BE39 0689 5704 9719 | B33: 2025-12-08 | C33: 6 | D33: 25 | E33: FR76 1027 8033 0000 0212 2090 181 | F33: Les Manalas Ecovoyageurs | I33: VIREMENT BELFIUS MOBILE VERS FR76 1027 8033 0000 0212 2090 181 Les Manalas Ecovoyageurs Abonnement personne physique REF. : 09054646C3525 VAL. 08-12 | J33: 2025-12-08 | K33: -20 | L33: EUR | M33: CMCIFR2A | O33: Abonnement personne physique | P33: VIREMENT BELFIUS MOBILE VERS FR | Q33: out | R33: 2025-12 | S33: 2025-Q4 | T33: Administration | U33: Admin Subscriptions
A34: BE39 0689 5704 9719 | B34: 2025-12-04 | C34: 6 | D34: 24 | E34: FR76 1680 7003 2338 2797 3321 161 | F34: SARL CMONEVENT | I34: VIREMENT BELFIUS MOBILE VERS FR76 1680 7003 2338 2797 3321 161 SARL CMONEVENT Emplacement exposant REF. : 09054120C4905 VAL. 04-12 | J34: 2025-12-04 | K34: -400 | L34: EUR | M34: CCBPFRPPGRE | O34: Emplacement exposant | P34: VIREMENT BELFIUS MOBILE VERS FR | Q34: out | R34: 2025-12 | S34: 2025-Q4 | T34: Marketing | U34: Events & Offline Marketing
A35: BE39 0689 5704 9719 | B35: 2025-12-04 | C35: 6 | D35: 23 | F35: RENDER.COM | H35: 94107 SAN FRANCISCO | I35: PAIEMENT DEBITMASTERCARD VIA eCommerce 03/12 RENDER. COM SAN FRANCISCO US 26,00 USD FRAIS DE TRAITEMENT 0,69 EUR + TVA 0,14 EUR CARTE N° 5255 0604 0603 9797 - de Biolley Sebastian COURS DE CHANGE 1,159161847 REF. : 0801UC4343385 VAL. 04-12 | J35: 2025-12-04 | K35: -23.26 | L35: EUR | N35: US | O35: PAIEMENT DEBITMASTERCARD VIA eCommerce 03/12 RENDER. COM SAN FRANCISCO US 26,00 USD FRAIS DE TRAITEMENT 0,69 EUR + TVA 0,14 EUR CARTE N° 5255 0604 0603 9797 - de Biolley Sebastian COURS DE CHANGE 1,159161847 REF. : 0801UC4343385 VAL. 04-12 | P35: PAIEMENT DEBITMASTERCARD VIA | Q35: out | R35: 2025-12 | S35: 2025-Q4 | T35: Technology | U35: Hosting & Infrastructure
A36: BE39 0689 5704 9719 | B36: 2025-12-04 | C36: 6 | D36: 22 | I36: FRAIS D'EXPEDITION DE VOS AVIS BANCAIRES REF. : 08170C3011059 VAL. 01-12 | J36: 2025-12-01 | K36: -2.99 | L36: EUR | O36: FRAIS D'EXPEDITION DE VOS AVIS BANCAIRES REF. : 08170C3011059 VAL. 01-12 | P36: FRAIS D | Q36: out | R36: 2025-12 | S36: 2025-Q4 | T36: Administration | U36: Banking Fees
A37: BE39 0689 5704 9719 | B37: 2025-12-03 | C37: 6 | D37: 21 | F37: EUSKADI LOW COST DONOS | H37: 20014 DONOSTIA/SAN | I37: ACHAT CARBURANT DEBITMASTERCARD 02/12 EUSKADI LOW COST DONOS DONOSTIA/SAN ES 86,59 EUR CARTE N° 5255 0604 0603 9797 - de Biolley Sebastian REF. : 0801SC3101891 VAL. 03-12 | J37: 2025-12-03 | K37: -86.59 | L37: EUR | N37: ES | O37: ACHAT CARBURANT DEBITMASTERCARD 02/12 EUSKADI LOW COST DONOS DONOSTIA/SAN ES 86,59 EUR CARTE N° 5255 0604 0603 9797 - de Biolley Sebastian REF. : 0801SC3101891 VAL. 03-12 | P37: ACHAT CARBURANT DEBITMASTERCARD | Q37: out | R37: 2025-12 | S37: 2025-Q4 | T37: Administration | U37: Office & Supplies
A38: BE39 0689 5704 9719 | B38: 2025-12-03 | C38: 6 | D38: 20 | F38: EUSKADI LOW COST DONOS | H38: 20014 DONOSTIA/SAN | I38: ACHAT CARBURANT DEBITMASTERCARD 02/12 EUSKADI LOW COST DONOS DONOSTIA/SAN ES 43,80 EUR CARTE N° 5255 0604 0603 9797 - de Biolley Sebastian REF. : 0801SC3101805 VAL. 03-12 | J38: 2025-12-03 | K38: -43.8 | L38: EUR | N38: ES | O38: ACHAT CARBURANT DEBITMASTERCARD 02/12 EUSKADI LOW COST DONOS DONOSTIA/SAN ES 43,80 EUR CARTE N° 5255 0604 0603 9797 - de Biolley Sebastian REF. : 0801SC3101805 VAL. 03-12 | P38: ACHAT CARBURANT DEBITMASTERCARD | Q38: out | R38: 2025-12 | S38: 2025-Q4 | T38: Administration | U38: Office & Supplies
A39: BE39 0689 5704 9719 | B39: 2025-11-26 | C39: 5 | D39: 19 | F39: SHARETRIBE | H39: 00130 HELSINKI | I39: PAIEMENT DEBITMASTERCARD VIA eCommerce 25/11 SHARETRIBE HELSINKI FI 369,00 USD FRAIS DE TRAITEMENT 4,44 EUR + TVA 0,93 EUR CARTE N° 5255 0604 0603 9797 - de Biolley Sebastian COURS DE CHANGE 1,150106097 REF. : 0801SBQ122503 VAL. 26-11 | J39: 2025-11-26 | K39: -326.21 | L39: EUR | N39: FI | O39: PAIEMENT DEBITMASTERCARD VIA eCommerce 25/11 SHARETRIBE HELSINKI FI 369,00 USD FRAIS DE TRAITEMENT 4,44 EUR + TVA 0,93 EUR CARTE N° 5255 0604 0603 9797 - de Biolley Sebastian COURS DE CHANGE 1,150106097 REF. : 0801SBQ122503 VAL. 26-11 | P39: PAIEMENT DEBITMASTERCARD VIA | Q39: out | R39: 2025-11 | S39: 2025-Q4 | T39: Technology | U39: Marketplace Platform
A40: BE39 0689 5704 9719 | B40: 2025-11-25 | C40: 5 | D40: 18 | F40: GOOGLE*ADS3215138576 | H40: D04 E5W5 CC GOOGLE.COM | I40: PAIEMENT DEBITMASTERCARD 24/11 GOOGLE*ADS3215138576 CC GOOGLE.COM IE 10,00 EUR CARTE N° 5255 0604 0603 9797 - de Biolley Sebastian REF. : 0801UBP192681 VAL. 25-11 | J40: 2025-11-25 | K40: -10 | L40: EUR | N40: IE | O40: PAIEMENT DEBITMASTERCARD 24/11 GOOGLE*ADS3215138576 CC GOOGLE.COM IE 10,00 EUR CARTE N° 5255 0604 0603 9797 - de Biolley Sebastian REF. : 0801UBP192681 VAL. 25-11 | P40: PAIEMENT DEBITMASTERCARD | Q40: out | R40: 2025-11 | S40: 2025-Q4 | T40: Marketing | U40: Paid Advertising
...

Sheet Summary
A1: Summary
A2: Total transactions | B2: 56
A3: Total inflow | B3: =SUMIF(Transactions!K2:K57,">0") -> 15000.1
A4: Total outflow | B4: =ABS(SUMIF(Transactions!K2:K57,"<0")) -> 11672.99
A5: Net | B5: =SUM(Transactions!K2:K57) -> 3327.11
A7: By category and subcategory
A8: Category | B8: Subcategory | C8: Amount
A9: (choose) | B9: (choose) | C9: =SUMIFS(Transactions!$K$2:$K$57,Transactions!$T$2:$T$57,"",Transactions!$U$2:$U$57,"") -> -375
A10: Revenue | B10: Platform Fees | C10: =SUMIFS(Transactions!$K$2:$K$57,Transactions!$T$2:$T$57,A10,Transactions!$U$2:$U$57,B10) -> 0
A11: Revenue | B11: Other Operating Revenue | C11: =SUMIFS(Transactions!$K$2:$K$57,Transactions!$T$2:$T$57,A11,Transactions!$U$2:$U$57,B11) -> 0.1
A12: Revenue | B12: Affiliate Commissions | C12: =SUMIFS(Transactions!$K$2:$K$57,Transactions!$T$2:$T$57,A12,Transactions!$U$2:$U$57,B12) -> 0
A13: Revenue | B13: Insurance Commissions | C13: =SUMIFS(Transactions!$K$2:$K$57,Transactions!$T$2:$T$57,A13,Transactions!$U$2:$U$57,B13) -> 0
A14: Revenue | B14: Refunds & Reimbursements | C14: =SUMIFS(Transactions!$K$2:$K$57,Transactions!$T$2:$T$57,A14,Transactions!$U$2:$U$57,B14) -> 0
A15: Revenue | B15: Interest Income | C15: =SUMIFS(Transactions!$K$2:$K$57,Transactions!$T$2:$T$57,A15,Transactions!$U$2:$U$57,B15) -> 0
A16: Revenue | B16: Other | C16: =SUMIFS(Transactions!$K$2:$K$57,Transactions!$T$2:$T$57,A16,Transactions!$U$2:$U$57,B16) -> 0
A17: Marketing | B17: Paid Advertising | C17: =SUMIFS(Transactions!$K$2:$K$57,Transactions!$T$2:$T$57,A17,Transactions!$U$2:$U$57,B17) -> -1233.26
A18: Marketing | B18: Events & Offline Marketing | C18: =SUMIFS(Transactions!$K$2:$K$57,Transactions!$T$2:$T$57,A18,Transactions!$U$2:$U$57,B18) -> -3309
A19: Marketing | B19: Travel (marketing-related) | C19: =SUMIFS(Transactions!$K$2:$K$57,Transactions!$T$2:$T$57,A19,Transactions!$U$2:$U$57,B19) -> 0
A20: Marketing | B20: Content & SEO | C20: =SUMIFS(Transactions!$K$2:$K$57,Transactions!$T$2:$T$57,A20,Transactions!$U$2:$U$57,B20) -> 0
A21: Marketing | B21: PR | C21: =SUMIFS(Transactions!$K$2:$K$57,Transactions!$T$2:$T$57,A21,Transactions!$U$2:$U$57,B21) -> 0
... A44: Capital & Financing | B44: Other | C44: =SUMIFS(Transactions!$K$2:$K$57,Transactions!$T$2:$T$57,A44,Transactions!$U$2:$U$57,B44) -> 0

Sheet Pivot
A1: Sum of Amount | B1: Column Labels
A2: Row Labels | B2: Administration | C2: Capital & Financing | D2: Marketing | E2: Revenue | F2: Technology | G2: (blank) | H2: Grand Total
A3: 2025-Q3 | C3: 8000 | E3: 7000 | H3: 15000
A4: 2025-09 | C4: 8000 | E4: 7000 | H4: 15000
A5: 2025-Q4 | B5: -1849.5 | D5: -1682.8 | E5: 0.1 | F5: -3713.78 | G5: -375 | H5: -7620.98
A6: 2025-10 | B6: -1688.89 | D6: -660 | F6: -323.47 | H6: -2672.36
A7: 2025-11 | B7: -7.23 | D7: -442.16 | E7: 0.1 | F7: -349.63 | G7: -375 | H7: -1173.92
A8: 2025-12 | B8: -153.38 | D8: -580.64 | F8: -3040.68 | H8: -3774.7
A9: 2026-Q1 | B9: -1054.65 | D9: -2859.46 | F9: -137.8 | H9: -4051.91
A10: 2026-01 | B10: -50.91 | D10: -238.59 | F10: -106.04 | H10: -395.54
A11: 2026-02 | B11: -1003.74 | D11: -1416.68 | F11: -31.76 | H11: -2452.18
A12: 2026-03 | D12: -1204.19 | H12: -1204.19
A13: Grand Total | B13: -2904.15 | C13: 8000 | D13: -4542.26 | E13: 7000.1 | F13: -3851.58 | G13: -375 | H13: 3327.11
